<?xml version='1.0' encoding='utf-8'?>
<mujoco model="humanoid_263"><compiler angle="radian" coordinate="local" /><default><joint limited="false" damping="1" /><geom type="sphere" size="0.02" /></default><asset><texture name="tex" type="2d" builtin="checker" width="100" height="100" /><material name="mat" texture="tex" reflectance="0.2" /></asset><worldbody><body name="root" pos="0 0 1"><joint name="root_tx" type="slide" axis="1 0 0" /><joint name="root_ty" type="slide" axis="0 1 0" /><joint name="root_tz" type="slide" axis="0 0 1" /><geom name="root_geom" type="sphere" size="0.05" rgba="0.3 0.3 0.9 1" /><body name="j0" pos="0 0 0"><joint name="j0_x" type="slide" axis="1 0 0" /><joint name="j0_y" type="slide" axis="0 1 0" /><joint name="j0_z" type="slide" axis="0 0 1" /><geom name="j0_geom" type="sphere" size="0.02" rgba="0.8 0.3 0.3 1" /><body name="j1" pos="0 0 0"><joint name="j1_x" type="slide" axis="1 0 0" /><joint name="j1_y" type="slide" axis="0 1 0" /><joint name="j1_z" type="slide" axis="0 0 1" /><geom name="j1_geom" type="sphere" size="0.02" rgba="0.8 0.3 0.3 1" /><body name="j2" pos="0 0 0"><joint name="j2_x" type="slide" axis="1 0 0" /><joint name="j2_y" type="slide" axis="0 1 0" /><joint name="j2_z" type="slide" axis="0 0 1" /><geom name="j2_geom" type="sphere" size="0.02" rgba="0.8 0.3 0.3 1" /><body name="j3" pos="0 0 0"><joint name="j3_x" type="slide" axis="1 0 0" /><joint name="j3_y" type="slide" axis="0 1 0" /><joint name="j3_z" type="slide" axis="0 0 1" /><geom name="j3_geom" type="sphere" size="0.02" rgba="0.8 0.3 0.3 1" /><body name="j4" pos="0 0 0"><joint name="j4_x" type="slide" axis="1 0 0" /><joint name="j4_y" type="slide" axis="0 1 0" /><joint name="j4_z" type="slide" axis="0 0 1" /><geom name="j4_geom" type="sphere" size="0.02" rgba="0.8 0.3 0.3 1" /><body name="j5" pos="0 0 0"><joint name="j5_x" type="slide" axis="1 0 0" /><joint name="j5_y" type="slide" axis="0 1 0" /><joint name="j5_z" type="slide" axis="0 0 1" /><geom name="j5_geom" type="sphere" size="0.02" rgba="0.8 0.3 0.3 1" /><body name="j6" pos="0 0 0"><joint name="j6_x" type="slide" axis="1 0 0" /><joint name="j6_y" type="slide" axis="0 1 0" /><joint name="j6_z" type="slide" axis="0 0 1" /><geom name="j6_geom" type="sphere" size="0.02" rgba="0.8 0.3 0.3 1" /><body name="j7" pos="0 0 0"><joint name="j7_x" type="slide" axis="1 0 0" /><joint name="j7_y" type="slide" axis="0 1 0" /><joint name="j7_z" type="slide" axis="0 0 1" /><geom name="j7_geom" type="sphere" size="0.02" rgba="0.8 0.3 0.3 1" /><body name="j8" pos="0 0 0"><joint name="j8_x" type="slide" axis="1 0 0" /><joint name="j8_y" type="slide" axis="0 1 0" /><joint name="j8_z" type="slide" axis="0 0 1" /><geom name="j8_geom" type="sphere" size="0.02" rgba="0.8 0.3 0.3 1" /><body name="j9" pos="0 0 0"><joint name="j9_x" type="slide" axis="1 0 0" /><joint name="j9_y" type="slide" axis="0 1 0" /><joint name="j9_z" type="slide" axis="0 0 1" /><geom name="j9_geom" type="sphere" size="0.02" rgba="0.8 0.3 0.3 1" /><body name="j10" pos="0 0 0"><joint name="j10_x" type="slide" axis="1 0 0" /><joint name="j10_y" type="slide" axis="0 1 0" /><joint name="j10_z" type="slide" axis="0 0 1" /><geom name="j10_geom" type="sphere" size="0.02" rgba="0.8 0.3 0.3 1" /><body name="j11" pos="0 0 0"><joint name="j11_x" type="slide" axis="1 0 0" /><joint name="j11_y" type="slide" axis="0 1 0" /><joint name="j11_z" type="slide" axis="0 0 1" /><geom name="j11_geom" type="sphere" size="0.02" rgba="0.8 0.3 0.3 1" /><body name="j12" pos="0 0 0"><joint name="j12_x" type="slide" axis="1 0 0" /><joint name="j12_y" type="slide" axis="0 1 0" /><joint name="j12_z" type="slide" axis="0 0 1" /><geom name="j12_geom" type="sphere" size="0.02" rgba="0.8 0.3 0.3 1" /><body name="j13" pos="0 0 0"><joint name="j13_x" type="slide" axis="1 0 0" /><joint name="j13_y" type="slide" axis="0 1 0" /><joint name="j13_z" type="slide" axis="0 0 1" /><geom name="j13_geom" type="sphere" size="0.02" rgba="0.8 0.3 0.3 1" /><body name="j14" pos="0 0 0"><joint name="j14_x" type="slide" axis="1 0 0" /><joint name="j14_y" type="slide" axis="0 1 0" /><joint name="j14_z" type="slide" axis="0 0 1" /><geom name="j14_geom" type="sphere" size="0.02" rgba="0.8 0.3 0.3 1" /><body name="j15" pos="0 0 0"><joint name="j15_x" type="slide" axis="1 0 0" /><joint name="j15_y" type="slide" axis="0 1 0" /><joint name="j15_z" type="slide" axis="0 0 1" /><geom name="j15_geom" type="sphere" size="0.02" rgba="0.8 0.3 0.3 1" /><body name="j16" pos="0 0 0"><joint name="j16_x" type="slide" axis="1 0 0" /><joint name="j16_y" type="slide" axis="0 1 0" /><joint name="j16_z" type="slide" axis="0 0 1" /><geom name="j16_geom" type="sphere" size="0.02" rgba="0.8 0.3 0.3 1" /><body name="j17" pos="0 0 0"><joint name="j17_x" type="slide" axis="1 0 0" /><joint name="j17_y" type="slide" axis="0 1 0" /><joint name="j17_z" type="slide" axis="0 0 1" /><geom name="j17_geom" type="sphere" size="0.02" rgba="0.8 0.3 0.3 1" /><body name="j18" pos="0 0 0"><joint name="j18_x" type="slide" axis="1 0 0" /><joint name="j18_y" type="slide" axis="0 1 0" /><joint name="j18_z" type="slide" axis="0 0 1" /><geom name="j18_geom" type="sphere" size="0.02" rgba="0.8 0.3 0.3 1" /><body name="j19" pos="0 0 0"><joint name="j19_x" type="slide" axis="1 0 0" /><joint name="j19_y" type="slide" axis="0 1 0" /><joint name="j19_z" type="slide" axis="0 0 1" /><geom name="j19_geom" type="sphere" size="0.02" rgba="0.8 0.3 0.3 1" /><body name="j20" pos="0 0 0"><joint name="j20_x" type="slide" axis="1 0 0" /><joint name="j20_y" type="slide" axis="0 1 0" /><joint name="j20_z" type="slide" axis="0 0 1" /><geom name="j20_geom" type="sphere" size="0.02" rgba="0.8 0.3 0.3 1" /><body name="j21" pos="0 0 0"><joint name="j21_x" type="slide" axis="1 0 0" /><joint name="j21_y" type="slide" axis="0 1 0" /><joint name="j21_z" type="slide" axis="0 0 1" /><geom name="j21_geom" type="sphere" size="0.02" rgba="0.8 0.3 0.3 1" /><body name="j22" pos="0 0 0"><joint name="j22_x" type="slide" axis="1 0 0" /><joint name="j22_y" type="slide" axis="0 1 0" /><joint name="j22_z" type="slide" axis="0 0 1" /><geom name="j22_geom" type="sphere" size="0.02" rgba="0.8 0.3 0.3 1" /><body name="j23" pos="0 0 0"><joint name="j23_x" type="slide" axis="1 0 0" /><joint name="j23_y" type="slide" axis="0 1 0" /><joint name="j23_z" type="slide" axis="0 0 1" /><geom name="j23_geom" type="sphere" size="0.02" rgba="0.8 0.3 0.3 1" /><body name="j24" pos="0 0 0"><joint name="j24_x" type="slide" axis="1 0 0" /><joint name="j24_y" type="slide" axis="0 1 0" /><joint name="j24_z" type="slide" axis="0 0 1" /><geom name="j24_geom" type="sphere" size="0.02" rgba="0.8 0.3 0.3 1" /><body name="j25" pos="0 0 0"><joint name="j25_x" type="slide" axis="1 0 0" /><joint name="j25_y" type="slide" axis="0 1 0" /><joint name="j25_z" type="slide" axis="0 0 1" /><geom name="j25_geom" type="sphere" size="0.02" rgba="0.8 0.3 0.3 1" /><body name="j26" pos="0 0 0"><joint name="j26_x" type="slide" axis="1 0 0" /><joint name="j26_y" type="slide" axis="0 1 0" /><joint name="j26_z" type="slide" axis="0 0 1" /><geom name="j26_geom" type="sphere" size="0.02" rgba="0.8 0.3 0.3 1" /><body name="j27" pos="0 0 0"><joint name="j27_x" type="slide" axis="1 0 0" /><joint name="j27_y" type="slide" axis="0 1 0" /><joint name="j27_z" type="slide" axis="0 0 1" /><geom name="j27_geom" type="sphere" size="0.02" rgba="0.8 0.3 0.3 1" /><body name="j28" pos="0 0 0"><joint name="j28_x" type="slide" axis="1 0 0" /><joint name="j28_y" type="slide" axis="0 1 0" /><joint name="j28_z" type="slide" axis="0 0 1" /><geom name="j28_geom" type="sphere" size="0.02" rgba="0.8 0.3 0.3 1" /><body name="j29" pos="0 0 0"><joint name="j29_x" type="slide" axis="1 0 0" /><joint name="j29_y" type="slide" axis="0 1 0" /><joint name="j29_z" type="slide" axis="0 0 1" /><geom name="j29_geom" type="sphere" size="0.02" rgba="0.8 0.3 0.3 1" /><body name="j30" pos="0 0 0"><joint name="j30_x" type="slide" axis="1 0 0" /><joint name="j30_y" type="slide" axis="0 1 0" /><joint name="j30_z" type="slide" axis="0 0 1" /><geom name="j30_geom" type="sphere" size="0.02" rgba="0.8 0.3 0.3 1" /><body name="j31" pos="0 0 0"><joint name="j31_x" type="slide" axis="1 0 0" /><joint name="j31_y" type="slide" axis="0 1 0" /><joint name="j31_z" type="slide" axis="0 0 1" /><geom name="j31_geom" type="sphere" size="0.02" rgba="0.8 0.3 0.3 1" /><body name="j32" pos="0 0 0"><joint name="j32_x" type="slide" axis="1 0 0" /><joint name="j32_y" type="slide" axis="0 1 0" /><joint name="j32_z" type="slide" axis="0 0 1" /><geom name="j32_geom" type="sphere" size="0.02" rgba="0.8 0.3 0.3 1" /><body name="j33" pos="0 0 0"><joint name="j33_x" type="slide" axis="1 0 0" /><joint name="j33_y" type="slide" axis="0 1 0" /><joint name="j33_z" type="slide" axis="0 0 1" /><geom name="j33_geom" type="sphere" size="0.02" rgba="0.8 0.3 0.3 1" /><body name="j34" pos="0 0 0"><joint name="j34_x" type="slide" axis="1 0 0" /><joint name="j34_y" type="slide" axis="0 1 0" /><joint name="j34_z" type="slide" axis="0 0 1" /><geom name="j34_geom" type="sphere" size="0.02" rgba="0.8 0.3 0.3 1" /><body name="j35" pos="0 0 0"><joint name="j35_x" type="slide" axis="1 0 0" /><joint name="j35_y" type="slide" axis="0 1 0" /><joint name="j35_z" type="slide" axis="0 0 1" /><geom name="j35_geom" type="sphere" size="0.02" rgba="0.8 0.3 0.3 1" /><body name="j36" pos="0 0 0"><joint name="j36_x" type="slide" axis="1 0 0" /><joint name="j36_y" type="slide" axis="0 1 0" /><joint name="j36_z" type="slide" axis="0 0 1" /><geom name="j36_geom" type="sphere" size="0.02" rgba="0.8 0.3 0.3 1" /><body name="j37" pos="0 0 0"><joint name="j37_x" type="slide" axis="1 0 0" /><joint name="j37_y" type="slide" axis="0 1 0" /><joint name="j37_z" type="slide" axis="0 0 1" /><geom name="j37_geom" type="sphere" size="0.02" rgba="0.8 0.3 0.3 1" /><body name="j38" pos="0 0 0"><joint name="j38_x" type="slide" axis="1 0 0" /><joint name="j38_y" type="slide" axis="0 1 0" /><joint name="j38_z" type="slide" axis="0 0 1" /><geom name="j38_geom" type="sphere" size="0.02" rgba="0.8 0.3 0.3 1" /><body name="j39" pos="0 0 0"><joint name="j39_x" type="slide" axis="1 0 0" /><joint name="j39_y" type="slide" axis="0 1 0" /><joint name="j39_z" type="slide" axis="0 0 1" /><geom name="j39_geom" type="sphere" size="0.02" rgba="0.8 0.3 0.3 1" /><body name="j40" pos="0 0 0"><joint name="j40_x" type="slide" axis="1 0 0" /><joint name="j40_y" type="slide" axis="0 1 0" /><joint name="j40_z" type="slide" axis="0 0 1" /><geom name="j40_geom" type="sphere" size="0.02" rgba="0.8 0.3 0.3 1" /><body name="j41" pos="0 0 0"><joint name="j41_x" type="slide" axis="1 0 0" /><joint name="j41_y" type="slide" axis="0 1 0" /><joint name="j41_z" type="slide" axis="0 0 1" /><geom name="j41_geom" type="sphere" size="0.02" rgba="0.8 0.3 0.3 1" /><body name="j42" pos="0 0 0"><joint name="j42_x" type="slide" axis="1 0 0" /><joint name="j42_y" type="slide" axis="0 1 0" /><joint name="j42_z" type="slide" axis="0 0 1" /><geom name="j42_geom" type="sphere" size="0.02" rgba="0.8 0.3 0.3 1" /><body name="j43" pos="0 0 0"><joint name="j43_x" type="slide" axis="1 0 0" /><joint name="j43_y" type="slide" axis="0 1 0" /><joint name="j43_z" type="slide" axis="0 0 1" /><geom name="j43_geom" type="sphere" size="0.02" rgba="0.8 0.3 0.3 1" /><body name="j44" pos="0 0 0"><joint name="j44_x" type="slide" axis="1 0 0" /><joint name="j44_y" type="slide" axis="0 1 0" /><joint name="j44_z" type="slide" axis="0 0 1" /><geom name="j44_geom" type="sphere" size="0.02" rgba="0.8 0.3 0.3 1" /><body name="j45" pos="0 0 0"><joint name="j45_x" type="slide" axis="1 0 0" /><joint name="j45_y" type="slide" axis="0 1 0" /><joint name="j45_z" type="slide" axis="0 0 1" /><geom name="j45_geom" type="sphere" size="0.02" rgba="0.8 0.3 0.3 1" /><body name="j46" pos="0 0 0"><joint name="j46_x" type="slide" axis="1 0 0" /><joint name="j46_y" type="slide" axis="0 1 0" /><joint name="j46_z" type="slide" axis="0 0 1" /><geom name="j46_geom" type="sphere" size="0.02" rgba="0.8 0.3 0.3 1" /><body name="j47" pos="0 0 0"><joint name="j47_x" type="slide" axis="1 0 0" /><joint name="j47_y" type="slide" axis="0 1 0" /><joint name="j47_z" type="slide" axis="0 0 1" /><geom name="j47_geom" type="sphere" size="0.02" rgba="0.8 0.3 0.3 1" /><body name="j48" pos="0 0 0"><joint name="j48_x" type="slide" axis="1 0 0" /><joint name="j48_y" type="slide" axis="0 1 0" /><joint name="j48_z" type="slide" axis="0 0 1" /><geom name="j48_geom" type="sphere" size="0.02" rgba="0.8 0.3 0.3 1" /><body name="j49" pos="0 0 0"><joint name="j49_x" type="slide" axis="1 0 0" /><joint name="j49_y" type="slide" axis="0 1 0" /><joint name="j49_z" type="slide" axis="0 0 1" /><geom name="j49_geom" type="sphere" size="0.02" rgba="0.8 0.3 0.3 1" /><body name="j50" pos="0 0 0"><joint name="j50_x" type="slide" axis="1 0 0" /><joint name="j50_y" type="slide" axis="0 1 0" /><joint name="j50_z" type="slide" axis="0 0 1" /><geom name="j50_geom" type="sphere" size="0.02" rgba="0.8 0.3 0.3 1" /><body name="j51" pos="0 0 0"><joint name="j51_x" type="slide" axis="1 0 0" /><joint name="j51_y" type="slide" axis="0 1 0" /><joint name="j51_z" type="slide" axis="0 0 1" /><geom name="j51_geom" type="sphere" size="0.02" rgba="0.8 0.3 0.3 1" /><body name="j52" pos="0 0 0"><joint name="j52_x" type="slide" axis="1 0 0" /><joint name="j52_y" type="slide" axis="0 1 0" /><joint name="j52_z" type="slide" axis="0 0 1" /><geom name="j52_geom" type="sphere" size="0.02" rgba="0.8 0.3 0.3 1" /><body name="j53" pos="0 0 0"><joint name="j53_x" type="slide" axis="1 0 0" /><joint name="j53_y" type="slide" axis="0 1 0" /><joint name="j53_z" type="slide" axis="0 0 1" /><geom name="j53_geom" type="sphere" size="0.02" rgba="0.8 0.3 0.3 1" /><body name="j54" pos="0 0 0"><joint name="j54_x" type="slide" axis="1 0 0" /><joint name="j54_y" type="slide" axis="0 1 0" /><joint name="j54_z" type="slide" axis="0 0 1" /><geom name="j54_geom" type="sphere" size="0.02" rgba="0.8 0.3 0.3 1" /><body name="j55" pos="0 0 0"><joint name="j55_x" type="slide" axis="1 0 0" /><joint name="j55_y" type="slide" axis="0 1 0" /><joint name="j55_z" type="slide" axis="0 0 1" /><geom name="j55_geom" type="sphere" size="0.02" rgba="0.8 0.3 0.3 1" /><body name="j56" pos="0 0 0"><joint name="j56_x" type="slide" axis="1 0 0" /><joint name="j56_y" type="slide" axis="0 1 0" /><joint name="j56_z" type="slide" axis="0 0 1" /><geom name="j56_geom" type="sphere" size="0.02" rgba="0.8 0.3 0.3 1" /><body name="j57" pos="0 0 0"><joint name="j57_x" type="slide" axis="1 0 0" /><joint name="j57_y" type="slide" axis="0 1 0" /><joint name="j57_z" type="slide" axis="0 0 1" /><geom name="j57_geom" type="sphere" size="0.02" rgba="0.8 0.3 0.3 1" /><body name="j58" pos="0 0 0"><joint name="j58_x" type="slide" axis="1 0 0" /><joint name="j58_y" type="slide" axis="0 1 0" /><joint name="j58_z" type="slide" axis="0 0 1" /><geom name="j58_geom" type="sphere" size="0.02" rgba="0.8 0.3 0.3 1" /><body name="j59" pos="0 0 0"><joint name="j59_x" type="slide" axis="1 0 0" /><joint name="j59_y" type="slide" axis="0 1 0" /><joint name="j59_z" type="slide" axis="0 0 1" /><geom name="j59_geom" type="sphere" size="0.02" rgba="0.8 0.3 0.3 1" /><body name="j60" pos="0 0 0"><joint name="j60_x" type="slide" axis="1 0 0" /><joint name="j60_y" type="slide" axis="0 1 0" /><joint name="j60_z" type="slide" axis="0 0 1" /><geom name="j60_geom" type="sphere" size="0.02" rgba="0.8 0.3 0.3 1" /><body name="j61" pos="0 0 0"><joint name="j61_x" type="slide" axis="1 0 0" /><joint name="j61_y" type="slide" axis="0 1 0" /><joint name="j61_z" type="slide" axis="0 0 1" /><geom name="j61_geom" type="sphere" size="0.02" rgba="0.8 0.3 0.3 1" /><body name="j62" pos="0 0 0"><joint name="j62_x" type="slide" axis="1 0 0" /><joint name="j62_y" type="slide" axis="0 1 0" /><joint name="j62_z" type="slide" axis="0 0 1" /><geom name="j62_geom" type="sphere" size="0.02" rgba="0.8 0.3 0.3 1" /><body name="j63" pos="0 0 0"><joint name="j63_x" type="slide" axis="1 0 0" /><joint name="j63_y" type="slide" axis="0 1 0" /><joint name="j63_z" type="slide" axis="0 0 1" /><geom name="j63_geom" type="sphere" size="0.02" rgba="0.8 0.3 0.3 1" /><body name="j64" pos="0 0 0"><joint name="j64_x" type="slide" axis="1 0 0" /><joint name="j64_y" type="slide" axis="0 1 0" /><joint name="j64_z" type="slide" axis="0 0 1" /><geom name="j64_geom" type="sphere" size="0.02" rgba="0.8 0.3 0.3 1" /><body name="j65" pos="0 0 0"><joint name="j65_x" type="slide" axis="1 0 0" /><joint name="j65_y" type="slide" axis="0 1 0" /><joint name="j65_z" type="slide" axis="0 0 1" /><geom name="j65_geom" type="sphere" size="0.02" rgba="0.8 0.3 0.3 1" /><body name="j66" pos="0 0 0"><joint name="j66_x" type="slide" axis="1 0 0" /><joint name="j66_y" type="slide" axis="0 1 0" /><joint name="j66_z" type="slide" axis="0 0 1" /><geom name="j66_geom" type="sphere" size="0.02" rgba="0.8 0.3 0.3 1" /><body name="j67" pos="0 0 0"><joint name="j67_x" type="slide" axis="1 0 0" /><joint name="j67_y" type="slide" axis="0 1 0" /><joint name="j67_z" type="slide" axis="0 0 1" /><geom name="j67_geom" type="sphere" size="0.02" rgba="0.8 0.3 0.3 1" /><body name="j68" pos="0 0 0"><joint name="j68_x" type="slide" axis="1 0 0" /><joint name="j68_y" type="slide" axis="0 1 0" /><joint name="j68_z" type="slide" axis="0 0 1" /><geom name="j68_geom" type="sphere" size="0.02" rgba="0.8 0.3 0.3 1" /><body name="j69" pos="0 0 0"><joint name="j69_x" type="slide" axis="1 0 0" /><joint name="j69_y" type="slide" axis="0 1 0" /><joint name="j69_z" type="slide" axis="0 0 1" /><geom name="j69_geom" type="sphere" size="0.02" rgba="0.8 0.3 0.3 1" /><body name="j70" pos="0 0 0"><joint name="j70_x" type="slide" axis="1 0 0" /><joint name="j70_y" type="slide" axis="0 1 0" /><joint name="j70_z" type="slide" axis="0 0 1" /><geom name="j70_geom" type="sphere" size="0.02" rgba="0.8 0.3 0.3 1" /><body name="j71" pos="0 0 0"><joint name="j71_x" type="slide" axis="1 0 0" /><joint name="j71_y" type="slide" axis="0 1 0" /><joint name="j71_z" type="slide" axis="0 0 1" /><geom name="j71_geom" type="sphere" size="0.02" rgba="0.8 0.3 0.3 1" /><body name="j72" pos="0 0 0"><joint name="j72_x" type="slide" axis="1 0 0" /><joint name="j72_y" type="slide" axis="0 1 0" /><joint name="j72_z" type="slide" axis="0 0 1" /><geom name="j72_geom" type="sphere" size="0.02" rgba="0.8 0.3 0.3 1" /><body name="j73" pos="0 0 0"><joint name="j73_x" type="slide" axis="1 0 0" /><joint name="j73_y" type="slide" axis="0 1 0" /><joint name="j73_z" type="slide" axis="0 0 1" /><geom name="j73_geom" type="sphere" size="0.02" rgba="0.8 0.3 0.3 1" /><body name="j74" pos="0 0 0"><joint name="j74_x" type="slide" axis="1 0 0" /><joint name="j74_y" type="slide" axis="0 1 0" /><joint name="j74_z" type="slide" axis="0 0 1" /><geom name="j74_geom" type="sphere" size="0.02" rgba="0.8 0.3 0.3 1" /><body name="j75" pos="0 0 0"><joint name="j75_x" type="slide" axis="1 0 0" /><joint name="j75_y" type="slide" axis="0 1 0" /><joint name="j75_z" type="slide" axis="0 0 1" /><geom name="j75_geom" type="sphere" size="0.02" rgba="0.8 0.3 0.3 1" /><body name="j76" pos="0 0 0"><joint name="j76_x" type="slide" axis="1 0 0" /><joint name="j76_y" type="slide" axis="0 1 0" /><joint name="j76_z" type="slide" axis="0 0 1" /><geom name="j76_geom" type="sphere" size="0.02" rgba="0.8 0.3 0.3 1" /><body name="j77" pos="0 0 0"><joint name="j77_x" type="slide" axis="1 0 0" /><joint name="j77_y" type="slide" axis="0 1 0" /><joint name="j77_z" type="slide" axis="0 0 1" /><geom name="j77_geom" type="sphere" size="0.02" rgba="0.8 0.3 0.3 1" /><body name="j78" pos="0 0 0"><joint name="j78_x" type="slide" axis="1 0 0" /><joint name="j78_y" type="slide" axis="0 1 0" /><joint name="j78_z" type="slide" axis="0 0 1" /><geom name="j78_geom" type="sphere" size="0.02" rgba="0.8 0.3 0.3 1" /><body name="j79" pos="0 0 0"><joint name="j79_x" type="slide" axis="1 0 0" /><joint name="j79_y" type="slide" axis="0 1 0" /><joint name="j79_z" type="slide" axis="0 0 1" /><geom name="j79_geom" type="sphere" size="0.02" rgba="0.8 0.3 0.3 1" /><body name="j80" pos="0 0 0"><joint name="j80_x" type="slide" axis="1 0 0" /><joint name="j80_y" type="slide" axis="0 1 0" /><joint name="j80_z" type="slide" axis="0 0 1" /><geom name="j80_geom" type="sphere" size="0.02" rgba="0.8 0.3 0.3 1" /><body name="j81" pos="0 0 0"><joint name="j81_x" type="slide" axis="1 0 0" /><joint name="j81_y" type="slide" axis="0 1 0" /><joint name="j81_z" type="slide" axis="0 0 1" /><geom name="j81_geom" type="sphere" size="0.02" rgba="0.8 0.3 0.3 1" /><body name="j82" pos="0 0 0"><joint name="j82_x" type="slide" axis="1 0 0" /><joint name="j82_y" type="slide" axis="0 1 0" /><joint name="j82_z" type="slide" axis="0 0 1" /><geom name="j82_geom" type="sphere" size="0.02" rgba="0.8 0.3 0.3 1" /><body name="j83" pos="0 0 0"><joint name="j83_x" type="slide" axis="1 0 0" /><joint name="j83_y" type="slide" axis="0 1 0" /><joint name="j83_z" type="slide" axis="0 0 1" /><geom name="j83_geom" type="sphere" size="0.02" rgba="0.8 0.3 0.3 1" /><body name="j84" pos="0 0 0"><joint name="j84_x" type="slide" axis="1 0 0" /><joint name="j84_y" type="slide" axis="0 1 0" /><joint name="j84_z" type="slide" axis="0 0 1" /><geom name="j84_geom" type="sphere" size="0.02" rgba="0.8 0.3 0.3 1" /><body name="j85" pos="0 0 0"><joint name="j85_x" type="slide" axis="1 0 0" /><joint name="j85_y" type="slide" axis="0 1 0" /><joint name="j85_z" type="slide" axis="0 0 1" /><geom name="j85_geom" type="sphere" size="0.02" rgba="0.8 0.3 0.3 1" /><body name="j86" pos="0 0 0"><joint name="j86_x" type="slide" axis="1 0 0" /><joint name="j86_y" type="slide" axis="0 1 0" /><joint name="j86_z" type="slide" axis="0 0 1" /><geom name="j86_geom" type="sphere" size="0.02" rgba="0.8 0.3 0.3 1" /></body></body></body></body></body></body></body></body></body></body></body></body></body></body></body></body></body></body></body></body></body></body></body></body></body></body></body></body></body></body></body></body></body></body></body></body></body></body></body></body></body></body></body></body></body></body></body></body></body></body></body></body></body></body></body></body></body></body></body></body></body></body></body></body></body></body></body></body></body></body></body></body></body></body></body></body></body></body></body></body></body></body></body></body></body></body></body></body></worldbody></mujoco>